Workbook

Sheet Leia-me
B2: Rateios FTD — consolidado 2026 | C2: VERSÃO DO CLIENTE — sem a aba Rateios (detalhe por colaborador). Todos os quadros continuam completos; o detalhe fica na versão interna.
B3: Faturamento de mão de obra por nota fiscal, centro de custo e rubrica de folha.
B5: As abas
B6: Resumo | C6: Visão do período: total faturado, quebra por grupo de rubrica e por mês, e o resultado da conferência.
B7: Centro de Custo | C7: Cada centro de custo mês a mês. É a base do rateio que o cliente distribui internamente.
B8: Notas Fiscais | C8: Uma linha por NF: folha, taxa e tributos, total, e a comparação com o Total Geral informado na origem.
B9: Consulta por NF | C9: Escolha uma nota e veja a distribuição dela por centro de custo e por grupo de rubrica, com a conferência contra o Total Geral.
B10: NF x Centro de Custo | C10: Como cada nota se reparte entre centros de custo. 1.266 combinações no período.
B11: Rubricas | C11: Todas as verbas de folha mês a mês, agrupadas.
B12: NF x Grupo | C12: Cada nota repartida por grupo de rubrica. Alimenta o segundo quadro da Consulta por NF.
B13: Rateios | C13: O detalhe linha a linha — colaborador, centro de custo, rubrica e valor. Só existe na versão interna: é 96% do peso do arquivo e a única aba com CPF, nome e salário.
B14: dRubricas / dCentroCusto | C14: Tabelas de apoio. São as únicas abas que você edita à mão (células em azul).
B16: Atualização mensal
B17: 1. | C17: Salve os rateios do mês na pasta de origem, no mesmo formato dos anteriores.
B18: 2. | C18: Nesta pasta: Dados > Atualizar Tudo. As abas Rateios, NF x Centro de Custo e Rubricas vêm das consultas e se atualizam sozinhas, inclusive com centros e rubricas novos.
B19: 3. | C19: Confira a aba Notas Fiscais: a coluna Situação tem que estar "OK" em todas as linhas. "Verificar" significa que a nota não fecha contra o Total Geral do arquivo de origem.
B20: 4. | C20: Confira a linha "Não listado" no fim das abas Centro de Custo e Rubricas. Se vier diferente de zero, apareceu um centro ou uma rubrica que ainda não está na lista — acrescente a linha e copie a fórmula ao lado.
B21: 5. | C21: Salve e envie ao cliente.
B23: As cinco dinâmicas sugeridas
B24: ① Composição | C24: Linhas: Grupo · Colunas: Competência · Valores: Soma de Valor. É a leitura por natureza de gasto.
B25: ② Centro de custo | C25: Linhas: Centro de Custo · Colunas: Competência · Valores: Soma de Valor. Filtro de valor nos 12 maiores para o gráfico.
B26: ③ Rubricas | C26: Linhas: Grupo › Código › Rubrica · Colunas: Competência · Valores: Soma de Valor. Layout Tabular, com Repetir Rótulos de Item.
B27: ④ Conferência | C27: Linhas: Competência › NF · Valores: Soma de Valor. É a que você cruza com o Total Geral.
B28: ⑤ Quadro | C28: Linhas: Competência · Valores: Contagem Distinta de CPF e Soma de Valor. Exige a base no Modelo de Dados.
B29: Segmentações | C29: Competência (Linha do Tempo), Emp, Centro de Custo, Grupo e Tipo — criadas uma vez e ligadas a todas por Segmentação > Conexões de Relatório.
B30: Atenção | C30: Nunca arraste Salário (R$) para Valores: ele se repete em cada rubrica do mesmo colaborador e a soma não significa nada. Use Média, numa dinâmica só de cadastro.
B32: Legenda
B33: Azul | C33: Valor digitado à mão — é onde você edita.
B34: Preto | C34: Fórmula. Não sobrescreva.
B35: Fundo amarelo | C35: Campo que precisa da sua conferência.
B36: Fundo vermelho | C36: Divergência encontrada.
B38: Pontos que pedem sua conferência
B39: 2 notas | C39: NF_027199 e NF_027200 não fecham contra o Total Geral informado na origem: −R$ 462.395,54 e −R$ 542,00. Estão marcadas como "Verificar" na aba Notas Fiscais e não foram corrigidas aqui.
B40: 11 centros sem código | C40: Onze descrições chegaram sem o código na frente, somando R$ 503.929,82 (1,5% do período). Três delas — ROTATIVA NOITE, ROTATIVA DIA e ACABAMENTO NOITE — já existem com código (650 e 660) e estão virando linha duplicada na distribuição. As outras oito (PRÉ IMPRESSÃO, FILIAL RECIFE, SOROCABA, FTD MACEIO, FILIAL - SAO JOSE DOS CAMPOS, EXPEDICAO, RIBEIRAO PRETO e uma que veio só como ".") não têm par codificado. Estão em vermelho na aba dCentroCusto — nada foi unificado por conta própria.
B42: O que mudou em relação ao modelo anterior
B43: Total Geral | C43: Saiu da base. Ele é a soma das rubricas mais taxa e tributo, e ao entrar no unpivot dobrava o faturamento: a soma da coluna Valor dava R$ 66.663.524 em vez de R$ 33.092.189. Agora ele fica só na aba Notas Fiscais, como conferência.
B44: Rubricas novas | C44: A consulta não tem mais a lista fixa de 135 colunas. Rubrica nova entra sozinha; o que não for reconhecido aparece na consulta de auditoria em vez de sumir.
B45: Linhas zeradas | C45: 102.324 das 196.071 linhas eram zero. Foram descartadas na consulta: a base caiu para 80.546 linhas.
B46: Centro de custo | C46: Padronizado na consulta: 95 grafias viraram 88 centros ("532- LOGITICA FILIAIS" e "532 - LOGISTICA FILIAIS" eram o mesmo).
B47: Salário e datas | C47: Salário virou número (era o texto "1.707,00 / M"). Admissão e demissão viraram datas; quem vinha como "Avulso" está marcado na coluna Vínculo.
...

Sheet Resumo
A1: Resumo do período
A2: Janeiro a julho de 2026 · todos os números vêm das demais abas, nada é digitado aqui.
A4: Total faturado no período | D4: Custo de folha | G4: Taxa e tributos
A5: =Rubricas!$K$100 -> 33092189 | D5: =SUMIF(Rubricas!$A$5:$A$98,"<>Taxa e tributos",Rubricas!$K$5:$K$98) -> 25546571 | G5: =SUMIF(Rubricas!$A$5:$A$98,"Taxa e tributos",Rubricas!$K$5:$K$98) -> 7545617.8
A7: Notas fiscais | D7: Centros de custo | G7: Notas a verificar
A8: =COUNTA('Notas Fiscais'!$C$5:$C$628) -> 624 | D8: =COUNTA('Centro de Custo'!$A$5:$A$92) -> 88 | G8: =COUNTIF('Notas Fiscais'!$K$5:$K$628,"Verificar") -> 2
A10: Valor não listado
A11: ='Notas Fiscais'!$H$629 -> 0
A13: Composição por grupo de rubrica
A14: Grupo | B14: jan | C14: fev | D14: mar | E14: abr | F14: mai | G14: jun | H14: jul | I14: Total (R$) | J14: % do total
A15: Salário e horas normais | B15: =SUMIF(Rubricas!$A$5:$A$98,$A15,Rubricas!D$5:D$98) -> 2022692.6 | C15: =SUMIF(Rubricas!$A$5:$A$98,$A15,Rubricas!E$5:E$98) -> 2446168.4 | D15: =SUMIF(Rubricas!$A$5:$A$98,$A15,Rubricas!F$5:F$98) -> 2426457.9 | E15: =SUMIF(Rubricas!$A$5:$A$98,$A15,Rubricas!G$5:G$98) -> 2093578.4 | F15: =SUMIF(Rubricas!$A$5:$A$98,$A15,Rubricas!H$5:H$98) -> 1557762.5 | G15: =SUMIF(Rubricas!$A$5:$A$98,$A15,Rubricas!I$5:I$98) -> 1206557.2 | H15: =SUMIF(Rubricas!$A$5:$A$98,$A15,Rubricas!J$5:J$98) -> 1228918.6 | I15: =SUM(B15:H15) -> 12982136 | J15: =IFERROR(I15/I$22,0) -> 0.39230211
A16: Horas extras e adicionais | B16: =SUMIF(Rubricas!$A$5:$A$98,$A16,Rubricas!D$5:D$98) -> 518190.04 | C16: =SUMIF(Rubricas!$A$5:$A$98,$A16,Rubricas!E$5:E$98) -> 540088.98 | D16: =SUMIF(Rubricas!$A$5:$A$98,$A16,Rubricas!F$5:F$98) -> 532357.01 | E16: =SUMIF(Rubricas!$A$5:$A$98,$A16,Rubricas!G$5:G$98) -> 295333.58 | F16: =SUMIF(Rubricas!$A$5:$A$98,$A16,Rubricas!H$5:H$98) -> 126844.73 | G16: =SUMIF(Rubricas!$A$5:$A$98,$A16,Rubricas!I$5:I$98) -> 137802.47 | H16: =SUMIF(Rubricas!$A$5:$A$98,$A16,Rubricas!J$5:J$98) -> 213532.35 | I16: =SUM(B16:H16) -> 2364149.2 | J16: =IFERROR(I16/I$22,0) -> 0.071441305
A17: Encargos e provisões | B17: =SUMIF(Rubricas!$A$5:$A$98,$A17,Rubricas!D$5:D$98) -> 1355529.1 | C17: =SUMIF(Rubricas!$A$5:$A$98,$A17,Rubricas!E$5:E$98) -> 1651410.9 | D17: =SUMIF(Rubricas!$A$5:$A$98,$A17,Rubricas!F$5:F$98) -> 1734686.9 | E17: =SUMIF(Rubricas!$A$5:$A$98,$A17,Rubricas!G$5:G$98) -> 1426663.8 | F17: =SUMIF(Rubricas!$A$5:$A$98,$A17,Rubricas!H$5:H$98) -> 971541.5 | G17: =SUMIF(Rubricas!$A$5:$A$98,$A17,Rubricas!I$5:I$98) -> 819558.1 | H17: =SUMIF(Rubricas!$A$5:$A$98,$A17,Rubricas!J$5:J$98) -> 803196.58 | I17: =SUM(B17:H17) -> 8762586.9 | J17: =IFERROR(I17/I$22,0) -> 0.26479321
A18: Benefícios | B18: =SUMIF(Rubricas!$A$5:$A$98,$A18,Rubricas!D$5:D$98) -> 579649.71 | C18: =SUMIF(Rubricas!$A$5:$A$98,$A18,Rubricas!E$5:E$98) -> 550729.09 | D18: =SUMIF(Rubricas!$A$5:$A$98,$A18,Rubricas!F$5:F$98) -> 601616.51 | E18: =SUMIF(Rubricas!$A$5:$A$98,$A18,Rubricas!G$5:G$98) -> 464935.49 | F18: =SUMIF(Rubricas!$A$5:$A$98,$A18,Rubricas!H$5:H$98) -> 325843.41 | G18: =SUMIF(Rubricas!$A$5:$A$98,$A18,Rubricas!I$5:I$98) -> 261494.07 | H18: =SUMIF(Rubricas!$A$5:$A$98,$A18,Rubricas!J$5:J$98) -> 240672.57 | I18: =SUM(B18:H18) -> 3024940.9 | J18: =IFERROR(I18/I$22,0) -> 0.091409512
A19: EPI, exames e diversos | B19: =SUMIF(Rubricas!$A$5:$A$98,$A19,Rubricas!D$5:D$98) -> 142312.65 | C19: =SUMIF(Rubricas!$A$5:$A$98,$A19,Rubricas!E$5:E$98) -> 328333.02 | D19: =SUMIF(Rubricas!$A$5:$A$98,$A19,Rubricas!F$5:F$98) -> 324649.6 | E19: =SUMIF(Rubricas!$A$5:$A$98,$A19,Rubricas!G$5:G$98) -> 238336.11 | F19: =SUMIF(Rubricas!$A$5:$A$98,$A19,Rubricas!H$5:H$98) -> 133613.03 | G19: =SUMIF(Rubricas!$A$5:$A$98,$A19,Rubricas!I$5:I$98) -> 191057.74 | H19: =SUMIF(Rubricas!$A$5:$A$98,$A19,Rubricas!J$5:J$98) -> 83474.24 | I19: =SUM(B19:H19) -> 1441776.4 | J19: =IFERROR(I19/I$22,0) -> 0.04356848
A20: Descontos | B20: =SUMIF(Rubricas!$A$5:$A$98,$A20,Rubricas!D$5:D$98) -> -608482.24 | C20: =SUMIF(Rubricas!$A$5:$A$98,$A20,Rubricas!E$5:E$98) -> -479649.46 | D20: =SUMIF(Rubricas!$A$5:$A$98,$A20,Rubricas!F$5:F$98) -> -644646.17 | E20: =SUMIF(Rubricas!$A$5:$A$98,$A20,Rubricas!G$5:G$98) -> -646385.12 | F20: =SUMIF(Rubricas!$A$5:$A$98,$A20,Rubricas!H$5:H$98) -> -208768.87 | G20: =SUMIF(Rubricas!$A$5:$A$98,$A20,Rubricas!I$5:I$98) -> -269720.12 | H20: =SUMIF(Rubricas!$A$5:$A$98,$A20,Rubricas!J$5:J$98) -> -171365.67 | I20: =SUM(B20:H20) -> -3029017.6 | J20: =IFERROR(I20/I$22,0) -> -0.091532707
A21: Taxa e tributos | B21: =SUMIF(Rubricas!$A$5:$A$98,$A21,Rubricas!D$5:D$98) -> 1171525.4 | C21: =SUMIF(Rubricas!$A$5:$A$98,$A21,Rubricas!E$5:E$98) -> 1464249 | D21: =SUMIF(Rubricas!$A$5:$A$98,$A21,Rubricas!F$5:F$98) -> 1456874 | E21: =SUMIF(Rubricas!$A$5:$A$98,$A21,Rubricas!G$5:G$98) -> 1127054.7 | F21: =SUMIF(Rubricas!$A$5:$A$98,$A21,Rubricas!H$5:H$98) -> 861719.42 | G21: =SUMIF(Rubricas!$A$5:$A$98,$A21,Rubricas!I$5:I$98) -> 662225.69 | H21: =SUMIF(Rubricas!$A$5:$A$98,$A21,Rubricas!J$5:J$98) -> 801969.65 | I21: =SUM(B21:H21) -> 7545617.8 | J21: =IFERROR(I21/I$22,0) -> 0.22801809
A22: Total faturado | B22: =SUM(B15:B21) -> 5181417.3 | C22: =SUM(C15:C21) -> 6501330 | D22: =SUM(D15:D21) -> 6431995.8 | E22: =SUM(E15:E21) -> 4999516.9 | F22: =SUM(F15:F21) -> 3768555.7 | G22: =SUM(G15:G21) -> 3008975.1 | H22: =SUM(H15:H21) -> 3200398.3 | I22: =SUM(I15:I21) -> 33092189
A24: Descontos entram com sinal negativo — o total da coluna já é o valor líquido faturado.

Sheet Centro de Custo
A1: Centro de Custo
A2: Valor faturado por centro de custo e competência. Calculado sobre a aba NF x Centro de Custo.
A3: chave do mês → | B3: 1 | C3: 2 | D3: 3 | E3: 4 | F3: 5 | G3: 6 | H3: 7
A4: Centro de Custo | B4: jan | C4: fev | D4: mar | E4: abr | F4: mai | G4: jun | H4: jul | I4: Total (R$) | J4: % do total
A5: 691 - EMBALAGEM DIA | B5: =SUMIFS('NF x Centro de Custo'!$H$5:$H$1270,'NF x Centro de Custo'!$E$5:$E$1270,$A5,'NF x Centro de Custo'!$A$5:$A$1270,B$3) -> 772833.92 | C5: =SUMIFS('NF x Centro de Custo'!$H$5:$H$1270,'NF x Centro de Custo'!$E$5:$E$1270,$A5,'NF x Centro de Custo'!$A$5:$A$1270,C$3) -> 693655.09 | D5: =SUMIFS('NF x Centro de Custo'!$H$5:$H$1270,'NF x Centro de Custo'!$E$5:$E$1270,$A5,'NF x Centro de Custo'!$A$5:$A$1270,D$3) -> 869674.34 | E5: =SUMIFS('NF x Centro de Custo'!$H$5:$H$1270,'NF x Centro de Custo'!$E$5:$E$1270,$A5,'NF x Centro de Custo'!$A$5:$A$1270,E$3) -> 740297.57 | F5: =SUMIFS('NF x Centro de Custo'!$H$5:$H$1270,'NF x Centro de Custo'!$E$5:$E$1270,$A5,'NF x Centro de Custo'!$A$5:$A$1270,F$3) -> 508267.39 | G5: =SUMIFS('NF x Centro de Custo'!$H$5:$H$1270,'NF x Centro de Custo'!$E$5:$E$1270,$A5,'NF x Centro de Custo'!$A$5:$A$1270,G$3) -> 77209.03 | H5: =SUMIFS('NF x Centro de Custo'!$H$5:$H$1270,'NF x Centro de Custo'!$E$5:$E$1270,$A5,'NF x Centro de Custo'!$A$5:$A$1270,H$3) -> 520873.44 | I5: =SUM(B5:H5) -> 4182810.8 | J5: =IFERROR(I5/I$94,0) -> 0.12639873
A6: 188 - VENDAS PNLD | B6: =SUMIFS('NF x Centro de Custo'!$H$5:$H$1270,'NF x Centro de Custo'!$E$5:$E$1270,$A6,'NF x Centro de Custo'!$A$5:$A$1270,B$3) -> 91831.69 | C6: =SUMIFS('NF x Centro de Custo'!$H$5:$H$1270,'NF x Centro de Custo'!$E$5:$E$1270,$A6,'NF x Centro de Custo'!$A$5:$A$1270,C$3) -> 823686.03 | D6: =SUMIFS('NF x Centro de Custo'!$H$5:$H$1270,'NF x Centro de Custo'!$E$5:$E$1270,$A6,'NF x Centro de Custo'!$A$5:$A$1270,D$3) -> 728760.96 | E6: =SUMIFS('NF x Centro de Custo'!$H$5:$H$1270,'NF x Centro de Custo'!$E$5:$E$1270,$A6,'NF x Centro de Custo'!$A$5:$A$1270,E$3) -> 676704.82 | F6: =SUMIFS('NF x Centro de Custo'!$H$5:$H$1270,'NF x Centro de Custo'!$E$5:$E$1270,$A6,'NF x Centro de Custo'!$A$5:$A$1270,F$3) -> 649545.21 | G6: =SUMIFS('NF x Centro de Custo'!$H$5:$H$1270,'NF x Centro de Custo'!$E$5:$E$1270,$A6,'NF x Centro de Custo'!$A$5:$A$1270,G$3) -> 730829.94 | H6: =SUMIFS('NF x Centro de Custo'!$H$5:$H$1270,'NF x Centro de Custo'!$E$5:$E$1270,$A6,'NF x Centro de Custo'!$A$5:$A$1270,H$3) -> 105347.32 | I6: =SUM(B6:H6) -> 3806706 | J6: =IFERROR(I6/I$94,0) -> 0.11503337
A7: 691 - EMBALAGEM TARDE | B7: =SUMIFS('NF x Centro de Custo'!$H$5:$H$1270,'NF x Centro de Custo'!$E$5:$E$1270,$A7,'NF x Centro de Custo'!$A$5:$A$1270,B$3) -> 633377.29 | C7: =SUMIFS('NF x Centro de Custo'!$H$5:$H$1270,'NF x Centro de Custo'!$E$5:$E$1270,$A7,'NF x Centro de Custo'!$A$5:$A$1270,C$3) -> 482348.72 | D7: =SUMIFS('NF x Centro de Custo'!$H$5:$H$1270,'NF x Centro de Custo'!$E$5:$E$1270,$A7,'NF x Centro de Custo'!$A$5:$A$1270,D$3) -> 763338.21 | E7: =SUMIFS('NF x Centro de Custo'!$H$5:$H$1270,'NF x Centro de Custo'!$E$5:$E$1270,$A7,'NF x Centro de Custo'!$A$5:$A$1270,E$3) -> 551547.47 | F7: =SUMIFS('NF x Centro de Custo'!$H$5:$H$1270,'NF x Centro de Custo'!$E$5:$E$1270,$A7,'NF x Centro de Custo'!$A$5:$A$1270,F$3) -> 376879.45 | G7: =SUMIFS('NF x Centro de Custo'!$H$5:$H$1270,'NF x Centro de Custo'!$E$5:$E$1270,$A7,'NF x Centro de Custo'!$A$5:$A$1270,G$3) -> 36741.3 | H7: =SUMIFS('NF x Centro de Custo'!$H$5:$H$1270,'NF x Centro de Custo'!$E$5:$E$1270,$A7,'NF x Centro de Custo'!$A$5:$A$1270,H$3) -> 311088.71 | I7: =SUM(B7:H7) -> 3155321.1 | J7: =IFERROR(I7/I$94,0) -> 0.095349423
A8: 721 - ARMAZENAGEM E EXPEDIÇÃO NOITE | B8: =SUMIFS('NF x Centro de Custo'!$H$5:$H$1270,'NF x Centro de Custo'!$E$5:$E$1270,$A8,'NF x Centro de Custo'!$A$5:$A$1270,B$3) -> 494884.36 | C8: =SUMIFS('NF x Centro de Custo'!$H$5:$H$1270,'NF x Centro de Custo'!$E$5:$E$1270,$A8,'NF x Centro de Custo'!$A$5:$A$1270,C$3) -> 473934.63 | D8: =SUMIFS('NF x Centro de Custo'!$H$5:$H$1270,'NF x Centro de Custo'!$E$5:$E$1270,$A8,'NF x Centro de Custo'!$A$5:$A$1270,D$3) -> 365715.16 | E8: =SUMIFS('NF x Centro de Custo'!$H$5:$H$1270,'NF x Centro de Custo'!$E$5:$E$1270,$A8,'NF x Centro de Custo'!$A$5:$A$1270,E$3) -> 285755.08 | F8: =SUMIFS('NF x Centro de Custo'!$H$5:$H$1270,'NF x Centro de Custo'!$E$5:$E$1270,$A8,'NF x Centro de Custo'!$A$5:$A$1270,F$3) -> 191178.51 | G8: =SUMIFS('NF x Centro de Custo'!$H$5:$H$1270,'NF x Centro de Custo'!$E$5:$E$1270,$A8,'NF x Centro de Custo'!$A$5:$A$1270,G$3) -> 201981.46 | H8: =SUMIFS('NF x Centro de Custo'!$H$5:$H$1270,'NF x Centro de Custo'!$E$5:$E$1270,$A8,'NF x Centro de Custo'!$A$5:$A$1270,H$3) -> 288247.03 | I8: =SUM(B8:H8) -> 2301696.2 | J8: =IFERROR(I8/I$94,0) -> 0.069554064
A9: 532 - LOGISTICA FILIAIS | B9: =SUMIFS('NF x Centro de Custo'!$H$5:$H$1270,'NF x Centro de Custo'!$E$5:$E$1270,$A9,'NF x Centro de Custo'!$A$5:$A$1270,B$3) -> 425952.77 | C9: =SUMIFS('NF x Centro de Custo'!$H$5:$H$1270,'NF x Centro de Custo'!$E$5:$E$1270,$A9,'NF x Centro de Custo'!$A$5:$A$1270,C$3) -> 578340.24 | D9: =SUMIFS('NF x Centro de Custo'!$H$5:$H$1270,'NF x Centro de Custo'!$E$5:$E$1270,$A9,'NF x Centro de Custo'!$A$5:$A$1270,D$3) -> 540774.98 | E9: =SUMIFS('NF x Centro de Custo'!$H$5:$H$1270,'NF x Centro de Custo'!$E$5:$E$1270,$A9,'NF x Centro de Custo'!$A$5:$A$1270,E$3) -> 259594.26 | F9: =SUMIFS('NF x Centro de Custo'!$H$5:$H$1270,'NF x Centro de Custo'!$E$5:$E$1270,$A9,'NF x Centro de Custo'!$A$5:$A$1270,F$3) -> 171075.07 | G9: =SUMIFS('NF x Centro de Custo'!$H$5:$H$1270,'NF x Centro de Custo'!$E$5:$E$1270,$A9,'NF x Centro de Custo'!$A$5:$A$1270,G$3) -> 189438.27 | H9: =SUMIFS('NF x Centro de Custo'!$H$5:$H$1270,'NF x Centro de Custo'!$E$5:$E$1270,$A9,'NF x Centro de Custo'!$A$5:$A$1270,H$3) -> 105729.31 | I9: =SUM(B9:H9) -> 2270904.9 | J9: =IFERROR(I9/I$94,0) -> 0.068623593
A10: 721 - ARMAZENAGEM E EXPEDIÇÃO DIA | B10: =SUMIFS('NF x Centro de Custo'!$H$5:$H$1270,'NF x Centro de Custo'!$E$5:$E$1270,$A10,'NF x Centro de Custo'!$A$5:$A$1270,B$3) -> 503845 | C10: =SUMIFS('NF x Centro de Custo'!$H$5:$H$1270,'NF x Centro de Custo'!$E$5:$E$1270,$A10,'NF x Centro de Custo'!$A$5:$A$1270,C$3) -> 438037.93 | D10: =SUMIFS('NF x Centro de Custo'!$H$5:$H$1270,'NF x Centro de Custo'!$E$5:$E$1270,$A10,'NF x Centro de Custo'!$A$5:$A$1270,D$3) -> 272785.53 | E10: =SUMIFS('NF x Centro de Custo'!$H$5:$H$1270,'NF x Centro de Custo'!$E$5:$E$1270,$A10,'NF x Centro de Custo'!$A$5:$A$1270,E$3) -> 245314.03 | F10: =SUMIFS('NF x Centro de Custo'!$H$5:$H$1270,'NF x Centro de Custo'!$E$5:$E$1270,$A10,'NF x Centro de Custo'!$A$5:$A$1270,F$3) -> 195914.82 | G10: =SUMIFS('NF x Centro de Custo'!$H$5:$H$1270,'NF x Centro de Custo'!$E$5:$E$1270,$A10,'NF x Centro de Custo'!$A$5:$A$1270,G$3) -> 186287.62 | H10: =SUMIFS('NF x Centro de Custo'!$H$5:$H$1270,'NF x Centro de Custo'!$E$5:$E$1270,$A10,'NF x Centro de Custo'!$A$5:$A$1270,H$3) -> 275983.42 | I10: =SUM(B10:H10) -> 2118168.4 | J10: =IFERROR(I10/I$94,0) -> 0.064008106
A11: 721 - ARMAZENAGEM E EXPEDIÇÃO TARDE | B11: =SUMIFS('NF x Centro de Custo'!$H$5:$H$1270,'NF x Centro de Custo'!$E$5:$E$1270,$A11,'NF x Centro de Custo'!$A$5:$A$1270,B$3) -> 390405.54 | C11: =SUMIFS('NF x Centro de Custo'!$H$5:$H$1270,'NF x Centro de Custo'!$E$5:$E$1270,$A11,'NF x Centro de Custo'!$A$5:$A$1270,C$3) -> 404330.59 | D11: =SUMIFS('NF x Centro de Custo'!$H$5:$H$1270,'NF x Centro de Custo'!$E$5:$E$1270,$A11,'NF x Centro de Custo'!$A$5:$A$1270,D$3) -> 203467.51 | E11: =SUMIFS('NF x Centro de Custo'!$H$5:$H$1270,'NF x Centro de Custo'!$E$5:$E$1270,$A11,'NF x Centro de Custo'!$A$5:$A$1270,E$3) -> 193015.03 | F11: =SUMIFS('NF x Centro de Custo'!$H$5:$H$1270,'NF x Centro de Custo'!$E$5:$E$1270,$A11,'NF x Centro de Custo'!$A$5:$A$1270,F$3) -> 195434.74 | G11: =SUMIFS('NF x Centro de Custo'!$H$5:$H$1270,'NF x Centro de Custo'!$E$5:$E$1270,$A11,'NF x Centro de Custo'!$A$5:$A$1270,G$3) -> 216361.41 | H11: =SUMIFS('NF x Centro de Custo'!$H$5:$H$1270,'NF x Centro de Custo'!$E$5:$E$1270,$A11,'NF x Centro de Custo'!$A$5:$A$1270,H$3) -> 208695.65 | I11: =SUM(B11:H11) -> 1811710.5 | J11: =IFERROR(I11/I$94,0) -> 0.054747374
A12: 660 - ACABAMENTO NOITE | B12: =SUMIFS('NF x Centro de Custo'!$H$5:$H$1270,'NF x Centro de Custo'!$E$5:$E$1270,$A12,'NF x Centro de Custo'!$A$5:$A$1270,B$3) -> 251356.84 | C12: =SUMIFS('NF x Centro de Custo'!$H$5:$H$1270,'NF x Centro de Custo'!$E$5:$E$1270,$A12,'NF x Centro de Custo'!$A$5:$A$1270,C$3) -> 300299.99 | D12: =SUMIFS('NF x Centro de Custo'!$H$5:$H$1270,'NF x Centro de Custo'!$E$5:$E$1270,$A12,'NF x Centro de Custo'!$A$5:$A$1270,D$3) -> 213086.59 | E12: =SUMIFS('NF x Centro de Custo'!$H$5:$H$1270,'NF x Centro de Custo'!$E$5:$E$1270,$A12,'NF x Centro de Custo'!$A$5:$A$1270,E$3) -> 105184.58 | F12: =SUMIFS('NF x Centro de Custo'!$H$5:$H$1270,'NF x Centro de Custo'!$E$5:$E$1270,$A12,'NF x Centro de Custo'!$A$5:$A$1270,F$3) -> 31589.14 | G12: =SUMIFS('NF x Centro de Custo'!$H$5:$H$1270,'NF x Centro de Custo'!$E$5:$E$1270,$A12,'NF x Centro de Custo'!$A$5:$A$1270,G$3) -> 87627.05 | H12: =SUMIFS('NF x Centro de Custo'!$H$5:$H$1270,'NF x Centro de Custo'!$E$5:$E$1270,$A12,'NF x Centro de Custo'!$A$5:$A$1270,H$3) -> 202599.47 | I12: =SUM(B12:H12) -> 1191743.7 | J12: =IFERROR(I12/I$94,0) -> 0.036012838
A13: 660 - ACABAMENTO DIA | B13: =SUMIFS('NF x Centro de Custo'!$H$5:$H$1270,'NF x Centro de Custo'!$E$5:$E$1270,$A13,'NF x Centro de Custo'!$A$5:$A$1270,B$3) -> 200446.48 | C13: =SUMIFS('NF x Centro de Custo'!$H$5:$H$1270,'NF x Centro de Custo'!$E$5:$E$1270,$A13,'NF x Centro de Custo'!$A$5:$A$1270,C$3) -> 205675.84 | D13: =SUMIFS('NF x Centro de Custo'!$H$5:$H$1270,'NF x Centro de Custo'!$E$5:$E$1270,$A13,'NF x Centro de Custo'!$A$5:$A$1270,D$3) -> 210202.89 | E13: =SUMIFS('NF x Centro de Custo'!$H$5:$H$1270,'NF x Centro de Custo'!$E$5:$E$1270,$A13,'NF x Centro de Custo'!$A$5:$A$1270,E$3) -> 155117.34 | F13: =SUMIFS('NF x Centro de Custo'!$H$5:$H$1270,'NF x Centro de Custo'!$E$5:$E$1270,$A13,'NF x Centro de Custo'!$A$5:$A$1270,F$3) -> 144776.34 | G13: =SUMIFS('NF x Centro de Custo'!$H$5:$H$1270,'NF x Centro de Custo'!$E$5:$E$1270,$A13,'NF x Centro de Custo'!$A$5:$A$1270,G$3) -> 120525.13 | H13: =SUMIFS('NF x Centro de Custo'!$H$5:$H$1270,'NF x Centro de Custo'!$E$5:$E$1270,$A13,'NF x Centro de Custo'!$A$5:$A$1270,H$3) -> 128946.27 | I13: =SUM(B13:H13) -> 1165690.3 | J13: =IFERROR(I13/I$94,0) -> 0.035225542
A14: 660 - ACABAMENTO TARDE | B14: =SUMIFS('NF x Centro de Custo'!$H$5:$H$1270,'NF x Centro de Custo'!$E$5:$E$1270,$A14,'NF x Centro de Custo'!$A$5:$A$1270,B$3) -> 184581.29 | C14: =SUMIFS('NF x Centro de Custo'!$H$5:$H$1270,'NF x Centro de Custo'!$E$5:$E$1270,$A14,'NF x Centro de Custo'!$A$5:$A$1270,C$3) -> 174892.01 | D14: =SUMIFS('NF x Centro de Custo'!$H$5:$H$1270,'NF x Centro de Custo'!$E$5:$E$1270,$A14,'NF x Centro de Custo'!$A$5:$A$1270,D$3) -> 176448.08 | E14: =SUMIFS('NF x Centro de Custo'!$H$5:$H$1270,'NF x Centro de Custo'!$E$5:$E$1270,$A14,'NF x Centro de Custo'!$A$5:$A$1270,E$3) -> 125154.69 | F14: =SUMIFS('NF x Centro de Custo'!$H$5:$H$1270,'NF x Centro de Custo'!$E$5:$E$1270,$A14,'NF x Centro de Custo'!$A$5:$A$1270,F$3) -> 131178.82 | G14: =SUMIFS('NF x Centro de Custo'!$H$5:$H$1270,'NF x Centro de Custo'!$E$5:$E$1270,$A14,'NF x Centro de Custo'!$A$5:$A$1270,G$3) -> 137378.54 | H14: =SUMIFS('NF x Centro de Custo'!$H$5:$H$1270,'NF x Centro de Custo'!$E$5:$E$1270,$A14,'NF x Centro de Custo'!$A$5:$A$1270,H$3) -> 142664.91 | I14: =SUM(B14:H14) -> 1072298.3 | J14: =IFERROR(I14/I$94,0) -> 0.032403367
A15: 720 - LOGISTICA TRANSPORTE | B15: =SUMIFS('NF x Centro de Custo'!$H$5:$H$1270,'NF x Centro de Custo'!$E$5:$E$1270,$A15,'NF x Centro de Custo'!$A$5:$A$1270,B$3) -> 242959.37 | C15: =SUMIFS('NF x Centro de Custo'!$H$5:$H$1270,'NF x Centro de Custo'!$E$5:$E$1270,$A15,'NF x Centro de Custo'!$A$5:$A$1270,C$3) -> 199109.91 | D15: =SUMIFS('NF x Centro de Custo'!$H$5:$H$1270,'NF x Centro de Custo'!$E$5:$E$1270,$A15,'NF x Centro de Custo'!$A$5:$A$1270,D$3) -> 201504.2 | E15: =SUMIFS('NF x Centro de Custo'!$H$5:$H$1270,'NF x Centro de Custo'!$E$5:$E$1270,$A15,'NF x Centro de Custo'!$A$5:$A$1270,E$3) -> 163747.97 | F15: =SUMIFS('NF x Centro de Custo'!$H$5:$H$1270,'NF x Centro de Custo'!$E$5:$E$1270,$A15,'NF x Centro de Custo'!$A$5:$A$1270,F$3) -> 113602.32 | G15: =SUMIFS('NF x Centro de Custo'!$H$5:$H$1270,'NF x Centro de Custo'!$E$5:$E$1270,$A15,'NF x Centro de Custo'!$A$5:$A$1270,G$3) -> 76645.094 | H15: =SUMIFS('NF x Centro de Custo'!$H$5:$H$1270,'NF x Centro de Custo'!$E$5:$E$1270,$A15,'NF x Centro de Custo'!$A$5:$A$1270,H$3) -> 41304.86 | I15: =SUM(B15:H15) -> 1038873.7 | J15: =IFERROR(I15/I$94,0) -> 0.031393321
A16: 432 - CENTRAL DE RELACIONAMENTO AO CLIENTE | B16: =SUMIFS('NF x Centro de Custo'!$H$5:$H$1270,'NF x Centro de Custo'!$E$5:$E$1270,$A16,'NF x Centro de Custo'!$A$5:$A$1270,B$3) -> 76528.79 | C16: =SUMIFS('NF x Centro de Custo'!$H$5:$H$1270,'NF x Centro de Custo'!$E$5:$E$1270,$A16,'NF x Centro de Custo'!$A$5:$A$1270,C$3) -> 192225.59 | D16: =SUMIFS('NF x Centro de Custo'!$H$5:$H$1270,'NF x Centro de Custo'!$E$5:$E$1270,$A16,'NF x Centro de Custo'!$A$5:$A$1270,D$3) -> 266617.97 | E16: =SUMIFS('NF x Centro de Custo'!$H$5:$H$1270,'NF x Centro de Custo'!$E$5:$E$1270,$A16,'NF x Centro de Custo'!$A$5:$A$1270,E$3) -> 202143 | F16: =SUMIFS('NF x Centro de Custo'!$H$5:$H$1270,'NF x Centro de Custo'!$E$5:$E$1270,$A16,'NF x Centro de Custo'!$A$5:$A$1270,F$3) -> 188837.87 | G16: =SUMIFS('NF x Centro de Custo'!$H$5:$H$1270,'NF x Centro de Custo'!$E$5:$E$1270,$A16,'NF x Centro de Custo'!$A$5:$A$1270,G$3) -> 107343.23 | H16: =SUMIFS('NF x Centro de Custo'!$H$5:$H$1270,'NF x Centro de Custo'!$E$5:$E$1270,$A16,'NF x Centro de Custo'!$A$5:$A$1270,H$3) -> 0 | I16: =SUM(B16:H16) -> 1033696.4 | J16: =IFERROR(I16/I$94,0) -> 0.031236871
... A92: 720 - LOGISTICA | B92: =SUMIFS('NF x Centro de Custo'!$H$5:$H$1270,'NF x Centro de Custo'!$E$5:$E$1270,$A92,'NF x Centro de Custo'!$A$5:$A$1270,B$3) -> 0 | C92: =SUMIFS('NF x Centro de Custo'!$H$5:$H$1270,'NF x Centro de Custo'!$E$5:$E$1270,$A92,'NF x Centro de Custo'!$A$5:$A$1270,C$3) -> 0 | D92: =SUMIFS('NF x Centro de Custo'!$H$5:$H$1270,'NF x Centro de Custo'!$E$5:$E$1270,$A92,'NF x Centro de Custo'!$A$5:$A$1270,D$3) -> 0 | E92: =SUMIFS('NF x Centro de Custo'!$H$5:$H$1270,'NF x Centro de Custo'!$E$5:$E$1270,$A92,'NF x Centro de Custo'!$A$5:$A$1270,E$3) -> 0 | F92: =SUMIFS('NF x Centro de Custo'!$H$5:$H$1270,'NF x Centro de Custo'!$E$5:$E$1270,$A92,'NF x Centro de Custo'!$A$5:$A$1270,F$3) -> 0 | G92: =SUMIFS('NF x Centro de Custo'!$H$5:$H$1270,'NF x Centro de Custo'!$E$5:$E$1270,$A92,'NF x Centro de Custo'!$A$5:$A$1270,G$3) -> 38 | H92: =SUMIFS('NF x Centro de Custo'!$H$5:$H$1270,'NF x Centro de Custo'!$E$5:$E$1270,$A92,'NF x Centro de Custo'!$A$5:$A$1270,H$3) -> 0 | I92: =SUM(B92:H92) -> 38 | J92: =IFERROR(I92/I$94,0) -> 1.1483072e-06
A93: Não listado (verificar) | B93: =ROUND(SUMIFS('NF x Centro de Custo'!$H$5:$H$1270,'NF x Centro de Custo'!$A$5:$A$1270,B$3)-SUM(B5:B92),2) -> 0 | C93: =ROUND(SUMIFS('NF x Centro de Custo'!$H$5:$H$1270,'NF x Centro de Custo'!$A$5:$A$1270,C$3)-SUM(C5:C92),2) -> 0 | D93: =ROUND(SUMIFS('NF x Centro de Custo'!$H$5:$H$1270,'NF x Centro de Custo'!$A$5:$A$1270,D$3)-SUM(D5:D92),2) -> 0 | E93: =ROUND(SUMIFS('NF x Centro de Custo'!$H$5:$H$1270,'NF x Centro de Custo'!$A$5:$A$1270,E$3)-SUM(E5:E92),2) -> 0 | F93: =ROUND(SUMIFS('NF x Centro de Custo'!$H$5:$H$1270,'NF x Centro de Custo'!$A$5:$A$1270,F$3)-SUM(F5:F92),2) -> 0 | G93: =ROUND(SUMIFS('NF x Centro de Custo'!$H$5:$H$1270,'NF x Centro de Custo'!$A$5:$A$1270,G$3)-SUM(G5:G92),2) -> 0 | H93: =ROUND(SUMIFS('NF x Centro de Custo'!$H$5:$H$1270,'NF x Centro de Custo'!$A$5:$A$1270,H$3)-SUM(H5:H92),2) -> 0 | I93: =SUM(B93:H93) -> 0
A94: Total geral | B94: =SUM(B5:B93) -> 5181417.3 | C94: =SUM(C5:C93) -> 6501330 | D94: =SUM(D5:D93) -> 6431995.8 | E94: =SUM(E5:E93) -> 4999516.9 | F94: =SUM(F5:F93) -> 3768555.7 | G94: =SUM(G5:G93) -> 3008975.1 | H94: =SUM(H5:H93) -> 3200398.3 | I94: =SUM(I5:I93) -> 33092189
A96: A linha "Não listado" compara o total da aba NF x Centro de Custo com a soma dos centros acima. Diferente de zero = centro novo que ainda não está na lista.

Sheet Notas Fiscais
A1: Notas Fiscais
A2: Uma linha por nota. As colunas em azul vêm do Total Geral informado nos arquivos de origem — é a conferência do mês.
A4: Mês | B4: Competência | C4: NF | D4: Empresa | E4: Centros | F4: Folha (R$) | G4: Taxa e tributos (R$) | H4: Total calculado (R$) | I4: Total Geral informado (R$) | J4: Diferença (R$) | K4: Situação
A5: 1 | B5: 46023 | C5: NDB_205429 | D5: 445 | E5: =COUNTIF('NF x Centro de Custo'!$C$5:$C$1270,$C5) -> 8 | F5: =SUMIFS('NF x Centro de Custo'!$F$5:$F$1270,'NF x Centro de Custo'!$C$5:$C$1270,$C5) -> 21419.9 | G5: =SUMIFS('NF x Centro de Custo'!$G$5:$G$1270,'NF x Centro de Custo'!$C$5:$C$1270,$C5) -> 0 | H5: =F5+G5 -> 21419.9 | I5: 21419.9 | J5: =ROUND(H5-I5,2) -> 0 | K5: =IF(ABS(J5)<0.05,"OK","Verificar") -> OK
A6: 1 | B6: 46023 | C6: NDB_205430 | D6: 451 | E6: =COUNTIF('NF x Centro de Custo'!$C$5:$C$1270,$C6) -> 1 | F6: =SUMIFS('NF x Centro de Custo'!$F$5:$F$1270,'NF x Centro de Custo'!$C$5:$C$1270,$C6) -> 765.45 | G6: =SUMIFS('NF x Centro de Custo'!$G$5:$G$1270,'NF x Centro de Custo'!$C$5:$C$1270,$C6) -> 0 | H6: =F6+G6 -> 765.45 | I6: 765.45 | J6: =ROUND(H6-I6,2) -> 0 | K6: =IF(ABS(J6)<0.05,"OK","Verificar") -> OK
A7: 1 | B7: 46023 | C7: NDB_205431 | D7: 451 | E7: =COUNTIF('NF x Centro de Custo'!$C$5:$C$1270,$C7) -> 1 | F7: =SUMIFS('NF x Centro de Custo'!$F$5:$F$1270,'NF x Centro de Custo'!$C$5:$C$1270,$C7) -> 2456.61 | G7: =SUMIFS('NF x Centro de Custo'!$G$5:$G$1270,'NF x Centro de Custo'!$C$5:$C$1270,$C7) -> 0 | H7: =F7+G7 -> 2456.61 | I7: 2456.61 | J7: =ROUND(H7-I7,2) -> 0 | K7: =IF(ABS(J7)<0.05,"OK","Verificar") -> OK
A8: 1 | B8: 46023 | C8: NDB_205432 | D8: 464 | E8: =COUNTIF('NF x Centro de Custo'!$C$5:$C$1270,$C8) -> 2 | F8: =SUMIFS('NF x Centro de Custo'!$F$5:$F$1270,'NF x Centro de Custo'!$C$5:$C$1270,$C8) -> 2593.35 | G8: =SUMIFS('NF x Centro de Custo'!$G$5:$G$1270,'NF x Centro de Custo'!$C$5:$C$1270,$C8) -> 0 | H8: =F8+G8 -> 2593.35 | I8: 2593.35 | J8: =ROUND(H8-I8,2) -> 0 | K8: =IF(ABS(J8)<0.05,"OK","Verificar") -> OK
A9: 1 | B9: 46023 | C9: NDB_205433 | D9: 468 | E9: =COUNTIF('NF x Centro de Custo'!$C$5:$C$1270,$C9) -> 1 | F9: =SUMIFS('NF x Centro de Custo'!$F$5:$F$1270,'NF x Centro de Custo'!$C$5:$C$1270,$C9) -> 3294.62 | G9: =SUMIFS('NF x Centro de Custo'!$G$5:$G$1270,'NF x Centro de Custo'!$C$5:$C$1270,$C9) -> 0 | H9: =F9+G9 -> 3294.62 | I9: 3294.62 | J9: =ROUND(H9-I9,2) -> 0 | K9: =IF(ABS(J9)<0.05,"OK","Verificar") -> OK
A10: 1 | B10: 46023 | C10: NDB_205434 | D10: 468 | E10: =COUNTIF('NF x Centro de Custo'!$C$5:$C$1270,$C10) -> 1 | F10: =SUMIFS('NF x Centro de Custo'!$F$5:$F$1270,'NF x Centro de Custo'!$C$5:$C$1270,$C10) -> 14813.15 | G10: =SUMIFS('NF x Centro de Custo'!$G$5:$G$1270,'NF x Centro de Custo'!$C$5:$C$1270,$C10) -> 0 | H10: =F10+G10 -> 14813.15 | I10: 14813.15 | J10: =ROUND(H10-I10,2) -> 0 | K10: =IF(ABS(J10)<0.05,"OK","Verificar") -> OK
A11: 1 | B11: 46023 | C11: NDB_205463 | D11: 448 | E11: =COUNTIF('NF x Centro de Custo'!$C$5:$C$1270,$C11) -> 2 | F11: =SUMIFS('NF x Centro de Custo'!$F$5:$F$1270,'NF x Centro de Custo'!$C$5:$C$1270,$C11) -> 2761.45 | G11: =SUMIFS('NF x Centro de Custo'!$G$5:$G$1270,'NF x Centro de Custo'!$C$5:$C$1270,$C11) -> 0 | H11: =F11+G11 -> 2761.45 | I11: 2761.45 | J11: =ROUND(H11-I11,2) -> 0 | K11: =IF(ABS(J11)<0.05,"OK","Verificar") -> OK
A12: 1 | B12: 46023 | C12: NDB_205469 | D12: 1420 | E12: =COUNTIF('NF x Centro de Custo'!$C$5:$C$1270,$C12) -> 1 | F12: =SUMIFS('NF x Centro de Custo'!$F$5:$F$1270,'NF x Centro de Custo'!$C$5:$C$1270,$C12) -> 1300.38 | G12: =SUMIFS('NF x Centro de Custo'!$G$5:$G$1270,'NF x Centro de Custo'!$C$5:$C$1270,$C12) -> 0 | H12: =F12+G12 -> 1300.38 | I12: 1300.38 | J12: =ROUND(H12-I12,2) -> 0 | K12: =IF(ABS(J12)<0.05,"OK","Verificar") -> OK
A13: 1 | B13: 46023 | C13: NF_026598 | D13: 476 | E13: =COUNTIF('NF x Centro de Custo'!$C$5:$C$1270,$C13) -> 2 | F13: =SUMIFS('NF x Centro de Custo'!$F$5:$F$1270,'NF x Centro de Custo'!$C$5:$C$1270,$C13) -> 5513.14 | G13: =SUMIFS('NF x Centro de Custo'!$G$5:$G$1270,'NF x Centro de Custo'!$C$5:$C$1270,$C13) -> 1708.49 | H13: =F13+G13 -> 7221.63 | I13: 7221.63 | J13: =ROUND(H13-I13,2) -> 0 | K13: =IF(ABS(J13)<0.05,"OK","Verificar") -> OK
A14: 1 | B14: 46023 | C14: NF_205435 | D14: 470 | E14: =COUNTIF('NF x Centro de Custo'!$C$5:$C$1270,$C14) -> 1 | F14: =SUMIFS('NF x Centro de Custo'!$F$5:$F$1270,'NF x Centro de Custo'!$C$5:$C$1270,$C14) -> 10773.96 | G14: =SUMIFS('NF x Centro de Custo'!$G$5:$G$1270,'NF x Centro de Custo'!$C$5:$C$1270,$C14) -> 0 | H14: =F14+G14 -> 10773.96 | I14: 10773.96 | J14: =ROUND(H14-I14,2) -> 0 | K14: =IF(ABS(J14)<0.05,"OK","Verificar") -> OK
A15: 1 | B15: 46023 | C15: NF_205436 | D15: 470 | E15: =COUNTIF('NF x Centro de Custo'!$C$5:$C$1270,$C15) -> 1 | F15: =SUMIFS('NF x Centro de Custo'!$F$5:$F$1270,'NF x Centro de Custo'!$C$5:$C$1270,$C15) -> 10766.45 | G15: =SUMIFS('NF x Centro de Custo'!$G$5:$G$1270,'NF x Centro de Custo'!$C$5:$C$1270,$C15) -> 0 | H15: =F15+G15 -> 10766.45 | I15: 10766.45 | J15: =ROUND(H15-I15,2) -> 0 | K15: =IF(ABS(J15)<0.05,"OK","Verificar") -> OK
A16: 1 | B16: 46023 | C16: NF_205437 | D16: 471 | E16: =COUNTIF('NF x Centro de Custo'!$C$5:$C$1270,$C16) -> 1 | F16: =SUMIFS('NF x Centro de Custo'!$F$5:$F$1270,'NF x Centro de Custo'!$C$5:$C$1270,$C16) -> 6732.7 | G16: =SUMIFS('NF x Centro de Custo'!$G$5:$G$1270,'NF x Centro de Custo'!$C$5:$C$1270,$C16) -> 0 | H16: =F16+G16 -> 6732.7 | I16: 6732.7 | J16: =ROUND(H16-I16,2) -> 0 | K16: =IF(ABS(J16)<0.05,"OK","Verificar") -> OK
... A628: 7 | B628: 46204 | C628: NF_205749 | D628: 1 | E628: =COUNTIF('NF x Centro de Custo'!$C$5:$C$1270,$C628) -> 1 | F628: =SUMIFS('NF x Centro de Custo'!$F$5:$F$1270,'NF x Centro de Custo'!$C$5:$C$1270,$C628) -> 743.59 | G628: =SUMIFS('NF x Centro de Custo'!$G$5:$G$1270,'NF x Centro de Custo'!$C$5:$C$1270,$C628) -> 0 | H628: =F628+G628 -> 743.59 | I628: 743.59 | J628: =ROUND(H628-I628,2) -> 0 | K628: =IF(ABS(J628)<0.05,"OK","Verificar") -> OK
C629: Não listado (verificar) | F629: =ROUND(SUM('NF x Centro de Custo'!$F$5:$F$1270)-SUM(F5:F628),2) -> 0 | G629: =ROUND(SUM('NF x Centro de Custo'!$G$5:$G$1270)-SUM(G5:G628),2) -> 0 | H629: =F629+G629 -> 0 | K629: =IF(ABS(H629)<0.05,"OK","Verificar") -> OK
C630: Total geral | F630: =SUM(F5:F629) -> 25546571 | G630: =SUM(G5:G629) -> 7545617.8 | H630: =SUM(H5:H629) -> 33092189 | I630: =SUM(I5:I629) -> 33555127 | J630: =SUM(J5:J629) -> -462937.54 | K630: =COUNTIF(K5:K629,"Verificar")&" a verificar" -> 2 a verificar
C632: Total calculado = folha + taxa + tributo somados a partir do detalhe. Total Geral informado = o que veio na planilha de rateio. Os dois têm que bater.
C633: A linha "Não listado" compara o total da aba NF x Centro de Custo com a soma das notas acima. Diferente de zero = nota nova que ainda não está nesta lista.

Sheet Consulta por NF
A1: Consulta por NF
A2: Escolha a nota na célula amarela e a distribuição dela aparece abaixo, por centro de custo e por grupo de rubrica.
A4: Nota fiscal | B4: NF_026173 | C4: ← clique na seta para escolher, ou digite o número
A6: Competência | B6: =IFERROR(INDEX('Notas Fiscais'!$B$5:$B$20000,MATCH($B$4,'Notas Fiscais'!$C$5:$C$20000,0)),"") -> 46082 | C6: Total calculado | D6: =IFERROR(INDEX('Notas Fiscais'!$H$5:$H$20000,MATCH($B$4,'Notas Fiscais'!$C$5:$C$20000,0)),"") -> 2432592.8
A7: Empresa | B7: =IFERROR(INDEX('Notas Fiscais'!$D$5:$D$20000,MATCH($B$4,'Notas Fiscais'!$C$5:$C$20000,0)),"") -> 448 | C7: Total Geral informado | D7: =IFERROR(INDEX('Notas Fiscais'!$I$5:$I$20000,MATCH($B$4,'Notas Fiscais'!$C$5:$C$20000,0)),"") -> 2432592.8
A8: Centros de custo | B8: =IFERROR(INDEX('Notas Fiscais'!$E$5:$E$20000,MATCH($B$4,'Notas Fiscais'!$C$5:$C$20000,0)),"") -> 14 | C8: Diferença | D8: =IFERROR(INDEX('Notas Fiscais'!$J$5:$J$20000,MATCH($B$4,'Notas Fiscais'!$C$5:$C$20000,0)),"") -> 0
A9: Folha | B9: =IFERROR(INDEX('Notas Fiscais'!$F$5:$F$20000,MATCH($B$4,'Notas Fiscais'!$C$5:$C$20000,0)),"") -> 1798183.5 | C9: Situação | D9: =IFERROR(INDEX('Notas Fiscais'!$K$5:$K$20000,MATCH($B$4,'Notas Fiscais'!$C$5:$C$20000,0)),"") -> OK
A10: Taxa e tributos | B10: =IFERROR(INDEX('Notas Fiscais'!$G$5:$G$20000,MATCH($B$4,'Notas Fiscais'!$C$5:$C$20000,0)),"") -> 634409.23
A12: Distribuição por centro de custo
A13: # | B13: Centro de custo | C13: Folha (R$) | D13: Taxa e tributos (R$) | E13: Total (R$) | F13: % da nota
A14: 1 | B14: =IFERROR(INDEX('NF x Centro de Custo'!$E$5:$E$20000,MATCH($B$4&"|"&$A14,'NF x Centro de Custo'!$J$5:$J$20000,0)),"") -> 605 - ADM. MANUTENÇÃO DE SERV. PREDIAIS P. GRAF | C14: =IFERROR(INDEX('NF x Centro de Custo'!$F$5:$F$20000,MATCH($B$4&"|"&$A14,'NF x Centro de Custo'!$J$5:$J$20000,0)),0) -> 40301.54 | D14: =IFERROR(INDEX('NF x Centro de Custo'!$G$5:$G$20000,MATCH($B$4&"|"&$A14,'NF x Centro de Custo'!$J$5:$J$20000,0)),0) -> 14203.69 | E14: =IFERROR(INDEX('NF x Centro de Custo'!$H$5:$H$20000,MATCH($B$4&"|"&$A14,'NF x Centro de Custo'!$J$5:$J$20000,0)),0) -> 54505.23 | F14: =IFERROR(E14/$D$6,"") -> 0.022406229
A15: 2 | B15: =IFERROR(INDEX('NF x Centro de Custo'!$E$5:$E$20000,MATCH($B$4&"|"&$A15,'NF x Centro de Custo'!$J$5:$J$20000,0)),"") -> 610 - CONTROLE DE QUALIDADE - PQ. GRÁFICO | C15: =IFERROR(INDEX('NF x Centro de Custo'!$F$5:$F$20000,MATCH($B$4&"|"&$A15,'NF x Centro de Custo'!$J$5:$J$20000,0)),0) -> 36895.99 | D15: =IFERROR(INDEX('NF x Centro de Custo'!$G$5:$G$20000,MATCH($B$4&"|"&$A15,'NF x Centro de Custo'!$J$5:$J$20000,0)),0) -> 13040.49 | E15: =IFERROR(INDEX('NF x Centro de Custo'!$H$5:$H$20000,MATCH($B$4&"|"&$A15,'NF x Centro de Custo'!$J$5:$J$20000,0)),0) -> 49936.48 | F15: =IFERROR(E15/$D$6,"") -> 0.020528089
A16: 3 | B16: =IFERROR(INDEX('NF x Centro de Custo'!$E$5:$E$20000,MATCH($B$4&"|"&$A16,'NF x Centro de Custo'!$J$5:$J$20000,0)),"") -> 650 - ROTATIVA DIA | C16: =IFERROR(INDEX('NF x Centro de Custo'!$F$5:$F$20000,MATCH($B$4&"|"&$A16,'NF x Centro de Custo'!$J$5:$J$20000,0)),0) -> 31301.01 | D16: =IFERROR(INDEX('NF x Centro de Custo'!$G$5:$G$20000,MATCH($B$4&"|"&$A16,'NF x Centro de Custo'!$J$5:$J$20000,0)),0) -> 11221.8 | E16: =IFERROR(INDEX('NF x Centro de Custo'!$H$5:$H$20000,MATCH($B$4&"|"&$A16,'NF x Centro de Custo'!$J$5:$J$20000,0)),0) -> 42522.81 | F16: =IFERROR(E16/$D$6,"") -> 0.017480447
A17: 4 | B17: =IFERROR(INDEX('NF x Centro de Custo'!$E$5:$E$20000,MATCH($B$4&"|"&$A17,'NF x Centro de Custo'!$J$5:$J$20000,0)),"") -> 650 - ROTATIVA NOITE | C17: =IFERROR(INDEX('NF x Centro de Custo'!$F$5:$F$20000,MATCH($B$4&"|"&$A17,'NF x Centro de Custo'!$J$5:$J$20000,0)),0) -> 55052.13 | D17: =IFERROR(INDEX('NF x Centro de Custo'!$G$5:$G$20000,MATCH($B$4&"|"&$A17,'NF x Centro de Custo'!$J$5:$J$20000,0)),0) -> 19319.25 | E17: =IFERROR(INDEX('NF x Centro de Custo'!$H$5:$H$20000,MATCH($B$4&"|"&$A17,'NF x Centro de Custo'!$J$5:$J$20000,0)),0) -> 74371.38 | F17: =IFERROR(E17/$D$6,"") -> 0.030572886
A18: 5 | B18: =IFERROR(INDEX('NF x Centro de Custo'!$E$5:$E$20000,MATCH($B$4&"|"&$A18,'NF x Centro de Custo'!$J$5:$J$20000,0)),"") -> 650 - ROTATIVA TARDE | C18: =IFERROR(INDEX('NF x Centro de Custo'!$F$5:$F$20000,MATCH($B$4&"|"&$A18,'NF x Centro de Custo'!$J$5:$J$20000,0)),0) -> 45415.76 | D18: =IFERROR(INDEX('NF x Centro de Custo'!$G$5:$G$20000,MATCH($B$4&"|"&$A18,'NF x Centro de Custo'!$J$5:$J$20000,0)),0) -> 16089.3 | E18: =IFERROR(INDEX('NF x Centro de Custo'!$H$5:$H$20000,MATCH($B$4&"|"&$A18,'NF x Centro de Custo'!$J$5:$J$20000,0)),0) -> 61505.06 | F18: =IFERROR(E18/$D$6,"") -> 0.025283747
A19: 6 | B19: =IFERROR(INDEX('NF x Centro de Custo'!$E$5:$E$20000,MATCH($B$4&"|"&$A19,'NF x Centro de Custo'!$J$5:$J$20000,0)),"") -> 660 - ACABAMENTO DIA | C19: =IFERROR(INDEX('NF x Centro de Custo'!$F$5:$F$20000,MATCH($B$4&"|"&$A19,'NF x Centro de Custo'!$J$5:$J$20000,0)),0) -> 140654.4 | D19: =IFERROR(INDEX('NF x Centro de Custo'!$G$5:$G$20000,MATCH($B$4&"|"&$A19,'NF x Centro de Custo'!$J$5:$J$20000,0)),0) -> 49475.37 | E19: =IFERROR(INDEX('NF x Centro de Custo'!$H$5:$H$20000,MATCH($B$4&"|"&$A19,'NF x Centro de Custo'!$J$5:$J$20000,0)),0) -> 190129.77 | F19: =IFERROR(E19/$D$6,"") -> 0.078159309
A20: 7 | B20: =IFERROR(INDEX('NF x Centro de Custo'!$E$5:$E$20000,MATCH($B$4&"|"&$A20,'NF x Centro de Custo'!$J$5:$J$20000,0)),"") -> 660 - ACABAMENTO NOITE | C20: =IFERROR(INDEX('NF x Centro de Custo'!$F$5:$F$20000,MATCH($B$4&"|"&$A20,'NF x Centro de Custo'!$J$5:$J$20000,0)),0) -> 146881.64 | D20: =IFERROR(INDEX('NF x Centro de Custo'!$G$5:$G$20000,MATCH($B$4&"|"&$A20,'NF x Centro de Custo'!$J$5:$J$20000,0)),0) -> 51592.66 | E20: =IFERROR(INDEX('NF x Centro de Custo'!$H$5:$H$20000,MATCH($B$4&"|"&$A20,'NF x Centro de Custo'!$J$5:$J$20000,0)),0) -> 198474.3 | F20: =IFERROR(E20/$D$6,"") -> 0.081589612
A21: 8 | B21: =IFERROR(INDEX('NF x Centro de Custo'!$E$5:$E$20000,MATCH($B$4&"|"&$A21,'NF x Centro de Custo'!$J$5:$J$20000,0)),"") -> 660 - ACABAMENTO TARDE | C21: =IFERROR(INDEX('NF x Centro de Custo'!$F$5:$F$20000,MATCH($B$4&"|"&$A21,'NF x Centro de Custo'!$J$5:$J$20000,0)),0) -> 118350.4 | D21: =IFERROR(INDEX('NF x Centro de Custo'!$G$5:$G$20000,MATCH($B$4&"|"&$A21,'NF x Centro de Custo'!$J$5:$J$20000,0)),0) -> 41768.33 | E21: =IFERROR(INDEX('NF x Centro de Custo'!$H$5:$H$20000,MATCH($B$4&"|"&$A21,'NF x Centro de Custo'!$J$5:$J$20000,0)),0) -> 160118.73 | F21: =IFERROR(E21/$D$6,"") -> 0.06582225
A22: 9 | B22: =IFERROR(INDEX('NF x Centro de Custo'!$E$5:$E$20000,MATCH($B$4&"|"&$A22,'NF x Centro de Custo'!$J$5:$J$20000,0)),"") -> 680 - H.HOMEM-PROD. HP DIGITAL | C22: =IFERROR(INDEX('NF x Centro de Custo'!$F$5:$F$20000,MATCH($B$4&"|"&$A22,'NF x Centro de Custo'!$J$5:$J$20000,0)),0) -> 4590.61 | D22: =IFERROR(INDEX('NF x Centro de Custo'!$G$5:$G$20000,MATCH($B$4&"|"&$A22,'NF x Centro de Custo'!$J$5:$J$20000,0)),0) -> 1614.5 | E22: =IFERROR(INDEX('NF x Centro de Custo'!$H$5:$H$20000,MATCH($B$4&"|"&$A22,'NF x Centro de Custo'!$J$5:$J$20000,0)),0) -> 6205.11 | F22: =IFERROR(E22/$D$6,"") -> 0.0025508215
A23: 10 | B23: =IFERROR(INDEX('NF x Centro de Custo'!$E$5:$E$20000,MATCH($B$4&"|"&$A23,'NF x Centro de Custo'!$J$5:$J$20000,0)),"") -> 691 - EMBALAGEM DIA | C23: =IFERROR(INDEX('NF x Centro de Custo'!$F$5:$F$20000,MATCH($B$4&"|"&$A23,'NF x Centro de Custo'!$J$5:$J$20000,0)),0) -> 572428.73 | D23: =IFERROR(INDEX('NF x Centro de Custo'!$G$5:$G$20000,MATCH($B$4&"|"&$A23,'NF x Centro de Custo'!$J$5:$J$20000,0)),0) -> 201884.69 | E23: =IFERROR(INDEX('NF x Centro de Custo'!$H$5:$H$20000,MATCH($B$4&"|"&$A23,'NF x Centro de Custo'!$J$5:$J$20000,0)),0) -> 774313.42 | F23: =IFERROR(E23/$D$6,"") -> 0.31830787
A24: 11 | B24: =IFERROR(INDEX('NF x Centro de Custo'!$E$5:$E$20000,MATCH($B$4&"|"&$A24,'NF x Centro de Custo'!$J$5:$J$20000,0)),"") -> 691 - EMBALAGEM TARDE | C24: =IFERROR(INDEX('NF x Centro de Custo'!$F$5:$F$20000,MATCH($B$4&"|"&$A24,'NF x Centro de Custo'!$J$5:$J$20000,0)),0) -> 500594.69 | D24: =IFERROR(INDEX('NF x Centro de Custo'!$G$5:$G$20000,MATCH($B$4&"|"&$A24,'NF x Centro de Custo'!$J$5:$J$20000,0)),0) -> 177048.9 | E24: =IFERROR(INDEX('NF x Centro de Custo'!$H$5:$H$20000,MATCH($B$4&"|"&$A24,'NF x Centro de Custo'!$J$5:$J$20000,0)),0) -> 677643.59 | F24: =IFERROR(E24/$D$6,"") -> 0.27856845
A25: 12 | B25: =IFERROR(INDEX('NF x Centro de Custo'!$E$5:$E$20000,MATCH($B$4&"|"&$A25,'NF x Centro de Custo'!$J$5:$J$20000,0)),"") -> 723 - RECEBIMENTO/ FATURAMENTO | C25: =IFERROR(INDEX('NF x Centro de Custo'!$F$5:$F$20000,MATCH($B$4&"|"&$A25,'NF x Centro de Custo'!$J$5:$J$20000,0)),0) -> 6580.74 | D25: =IFERROR(INDEX('NF x Centro de Custo'!$G$5:$G$20000,MATCH($B$4&"|"&$A25,'NF x Centro de Custo'!$J$5:$J$20000,0)),0) -> 2313.46 | E25: =IFERROR(INDEX('NF x Centro de Custo'!$H$5:$H$20000,MATCH($B$4&"|"&$A25,'NF x Centro de Custo'!$J$5:$J$20000,0)),0) -> 8894.2 | F25: =IFERROR(E25/$D$6,"") -> 0.0036562635
... A37: 24 | B37: =IFERROR(INDEX('NF x Centro de Custo'!$E$5:$E$20000,MATCH($B$4&"|"&$A37,'NF x Centro de Custo'!$J$5:$J$20000,0)),"") | C37: =IFERROR(INDEX('NF x Centro de Custo'!$F$5:$F$20000,MATCH($B$4&"|"&$A37,'NF x Centro de Custo'!$J$5:$J$20000,0)),0) -> 0 | D37: =IFERROR(INDEX('NF x Centro de Custo'!$G$5:$G$20000,MATCH($B$4&"|"&$A37,'NF x Centro de Custo'!$J$5:$J$20000,0)),0) -> 0 | E37: =IFERROR(INDEX('NF x Centro de Custo'!$H$5:$H$20000,MATCH($B$4&"|"&$A37,'NF x Centro de Custo'!$J$5:$J$20000,0)),0) -> 0 | F37: =IFERROR(E37/$D$6,"") -> 0
B38: Total da nota | C38: =SUM(C14:C37) -> 1798183.5 | D38: =SUM(D14:D37) -> 634409.23 | E38: =SUM(E14:E37) -> 2432592.8
B39: =IF(ROUND(E38-$D$6,2)=0,"","Atenção: esta nota tem mais de 24 centros de custo — veja a lista completa na aba NF x Centro de Custo.")
A41: Composição por grupo de rubrica
B42: Grupo | C42: Valor (R$) | D42: % da nota
B43: Salário e horas normais | C43: =SUMIFS('NF x Grupo'!$D$5:$D$20000,'NF x Grupo'!$B$5:$B$20000,$B$4,'NF x Grupo'!$C$5:$C$20000,$B43) -> 923873.17 | D43: =IFERROR(C43/$D$6,"") -> 0.37978949
B44: Horas extras e adicionais | C44: =SUMIFS('NF x Grupo'!$D$5:$D$20000,'NF x Grupo'!$B$5:$B$20000,$B$4,'NF x Grupo'!$C$5:$C$20000,$B44) -> 273469.09 | D44: =IFERROR(C44/$D$6,"") -> 0.11241877
B45: Encargos e provisões | C45: =SUMIFS('NF x Grupo'!$D$5:$D$20000,'NF x Grupo'!$B$5:$B$20000,$B$4,'NF x Grupo'!$C$5:$C$20000,$B45) -> 720110.57 | D45: =IFERROR(C45/$D$6,"") -> 0.29602594
B46: Benefícios | C46: =SUMIFS('NF x Grupo'!$D$5:$D$20000,'NF x Grupo'!$B$5:$B$20000,$B$4,'NF x Grupo'!$C$5:$C$20000,$B46) -> 0 | D46: =IFERROR(C46/$D$6,"") -> 0
B47: EPI, exames e diversos | C47: =SUMIFS('NF x Grupo'!$D$5:$D$20000,'NF x Grupo'!$B$5:$B$20000,$B$4,'NF x Grupo'!$C$5:$C$20000,$B47) -> 87788.3 | D47: =IFERROR(C47/$D$6,"") -> 0.036088367
B48: Descontos | C48: =SUMIFS('NF x Grupo'!$D$5:$D$20000,'NF x Grupo'!$B$5:$B$20000,$B$4,'NF x Grupo'!$C$5:$C$20000,$B48) -> -207057.6 | D48: =IFERROR(C48/$D$6,"") -> -0.08511807
B49: Taxa e tributos | C49: =SUMIFS('NF x Grupo'!$D$5:$D$20000,'NF x Grupo'!$B$5:$B$20000,$B$4,'NF x Grupo'!$C$5:$C$20000,$B49) -> 634409.23 | D49: =IFERROR(C49/$D$6,"") -> 0.26079549
B50: Total da nota | C50: =SUM(C43:C49) -> 2432592.8
A52: Os três totais desta página — a soma dos centros, a soma dos grupos e o Total calculado do quadro acima — têm que dar o mesmo valor. O detalhe por colaborador está na aba Rateios da versão completa, filtrando pela NF.

Sheet NF x Centro de Custo
A1: NF x Centro de Custo
A2: Como cada nota fiscal se reparte entre os centros de custo. Saída da consulta — atualiza com Dados > Atualizar Tudo.
A4: Mês | B4: Competência | C4: NF | D4: Empresa | E4: Centro de Custo | F4: Folha (R$) | G4: Taxa e tributos (R$) | H4: Total (R$) | I4: Ordem na nota | J4: Chave
A5: 1 | B5: 46023 | C5: NDB_205429 | D5: 445 | E5: . | F5: 12 | G5: 0 | H5: 12 | I5: 1 | J5: NDB_205429|1
A6: 1 | B6: 46023 | C6: NDB_205429 | D6: 445 | E6: 193 - CONTROLADORIA -FTD | F6: 1081.35 | G6: 0 | H6: 1081.35 | I6: 2 | J6: NDB_205429|2
A7: 1 | B7: 46023 | C7: NDB_205429 | D7: 445 | E7: 210 - CONTROLADORIA | F7: 1802.95 | G7: 0 | H7: 1802.95 | I7: 3 | J7: NDB_205429|3
A8: 1 | B8: 46023 | C8: NDB_205429 | D8: 445 | E8: 220 - CP E TESOUR | F8: 2286 | G8: 0 | H8: 2286 | I8: 4 | J8: NDB_205429|4
A9: 1 | B9: 46023 | C9: NDB_205429 | D9: 445 | E9: 362 - RECRUTAMENTO E SELEÇÃO | F9: 1241.55 | G9: 0 | H9: 1241.55 | I9: 5 | J9: NDB_205429|5
A10: 1 | B10: 46023 | C10: NDB_205429 | D10: 445 | E10: 432 - CENTRAL DE RELACIONAMENTO AO CLIENTE | F10: 11966.8 | G10: 0 | H10: 11966.8 | I10: 6 | J10: NDB_205429|6
A11: 1 | B11: 46023 | C11: NDB_205429 | D11: 445 | E11: 434 - AVALIAÇÃO E FORMAÇÃO DE EDUCADORES | F11: 2428.5 | G11: 0 | H11: 2428.5 | I11: 7 | J11: NDB_205429|7
A12: 1 | B12: 46023 | C12: NDB_205429 | D12: 445 | E12: 540 - GERÊNCIA DE EXPERIÊNCIA AO CLIENTE | F12: 600.75 | G12: 0 | H12: 600.75 | I12: 8 | J12: NDB_205429|8
A13: 1 | B13: 46023 | C13: NDB_205430 | D13: 451 | E13: 482 - FILIAL BELO HORIZONTE | F13: 765.45 | G13: 0 | H13: 765.45 | I13: 1 | J13: NDB_205430|1
A14: 1 | B14: 46023 | C14: NDB_205431 | D14: 451 | E14: 532 - LOGISTICA FILIAIS | F14: 2456.61 | G14: 0 | H14: 2456.61 | I14: 1 | J14: NDB_205431|1
A15: 1 | B15: 46023 | C15: NDB_205432 | D15: 464 | E15: 1481 - FILIAL RIO DE JANEIRO | F15: 2515.85 | G15: 0 | H15: 2515.85 | I15: 1 | J15: NDB_205432|1
A16: 1 | B16: 46023 | C16: NDB_205432 | D16: 464 | E16: 481 - FILIAL RIO DE JANEIRO | F16: 77.5 | G16: 0 | H16: 77.5 | I16: 2 | J16: NDB_205432|2
... A1270: 7 | B1270: 46204 | C1270: NF_205749 | D1270: 1 | E1270: 425 - FTD BELEM | F1270: 743.59 | G1270: 0 | H1270: 743.59 | I1270: 1 | J1270: NF_205749|1
E1272: "Ordem na nota" e "Chave" numeram os centros dentro de cada nota. São o que a aba Consulta por NF usa para montar a distribuição — vêm da consulta, não mexa.

Sheet NF x Grupo
A1: NF x Grupo
A2: Cada nota repartida por grupo de rubrica. Saída da consulta — é o que alimenta o segundo quadro da Consulta por NF.
A4: Mês | B4: NF | C4: Grupo | D4: Valor (R$)
A5: 1 | B5: NDB_205429 | C5: Benefícios | D5: 20410.4
A6: 1 | B6: NDB_205429 | C6: EPI, exames e diversos | D6: 1009.5
A7: 1 | B7: NDB_205430 | C7: Benefícios | D7: 753.45
A8: 1 | B8: NDB_205430 | C8: EPI, exames e diversos | D8: 12
A9: 1 | B9: NDB_205431 | C9: Benefícios | D9: 2365.61
A10: 1 | B10: NDB_205431 | C10: EPI, exames e diversos | D10: 91
A11: 1 | B11: NDB_205432 | C11: Benefícios | D11: 2399.05
A12: 1 | B12: NDB_205432 | C12: EPI, exames e diversos | D12: 194.3
A13: 1 | B13: NDB_205433 | C13: Benefícios | D13: 3112.62
A14: 1 | B14: NDB_205433 | C14: EPI, exames e diversos | D14: 182
A15: 1 | B15: NDB_205434 | C15: Benefícios | D15: 14048.65
A16: 1 | B16: NDB_205434 | C16: EPI, exames e diversos | D16: 764.5
... A2198: 7 | B2198: NF_205749 | C2198: Benefícios | D2198: 743.59

Sheet Rubricas
A1: Rubricas
A2: Todas as verbas de folha do período, mês a mês. Saída da consulta — atualiza com Dados > Atualizar Tudo.
A4: Grupo | B4: Código | C4: Rubrica | D4: jan | E4: fev | F4: mar | G4: abr | H4: mai | I4: jun | J4: jul | K4: Total (R$) | L4: % do total
A5: Benefícios | B5: 136 | C5: REEMB.BENEFICIOS VR | D5: 32.33 | E5: 0 | F5: 0 | G5: 0 | H5: 0 | I5: 312.68 | J5: 172.6 | K5: =SUM(D5:J5) -> 517.61 | L5: =IFERROR(K5/K$100,0) -> 1.5641455e-05
A6: Benefícios | B6: 137 | C6: REEMB.BENEFICIOS VT | D6: 9.9 | E6: 124.32 | F6: 0 | G6: 0 | H6: 0 | I6: 181.82 | J6: 40 | K6: =SUM(D6:J6) -> 356.04 | L6: =IFERROR(K6/K$100,0) -> 1.0759034e-05
A7: Benefícios | B7: 276 | C7: PAGAMENTO DE VALE-TRANSPORTE (Valor) | D7: 377658.88 | E7: 277386.72 | F7: 313058.48 | G7: 247759.45 | H7: 166648.44 | I7: 114477.58 | J7: 183920.14 | K7: =SUM(D7:J7) -> 1680909.7 | L7: =IFERROR(K7/K$100,0) -> 0.050794757
A8: Benefícios | B8: 277 | C8: VALE REFEIÇÃO (Valor) | D8: 155129.7 | E8: 230068.85 | F8: 237892.73 | G8: 171004.64 | H8: 133816.65 | I8: 133518.19 | J8: 23519.63 | K8: =SUM(D8:J8) -> 1084950.4 | L8: =IFERROR(K8/K$100,0) -> 0.032785694
A9: Benefícios | B9: 284 | C9: PAGTO DE VALE ALIMENTACAO | D9: 0 | E9: 0 | F9: 0 | G9: 0 | H9: 0 | I9: 110 | J9: 0 | K9: =SUM(D9:J9) -> 110 | L9: =IFERROR(K9/K$100,0) -> 3.3240472e-06
A10: Benefícios | B10: 284 | C10: PAGTO DE VALE ALIMENTACAO (Valor) | D10: 46818.9 | E10: 0 | F10: 50623.3 | G10: 46039.4 | H10: 24888.12 | I10: 12893.8 | J10: 33020.2 | K10: =SUM(D10:J10) -> 214283.72 | L10: =IFERROR(K10/K$100,0) -> 0.0064753564
A11: Benefícios | B11: 284 | C11: PAGTO DE VALE ALIMENTACAO DIF. DISSIDIO (Valor) | D11: 0 | E11: 42410.2 | F11: 0 | G11: 0 | H11: 0 | I11: 0 | J11: 0 | K11: =SUM(D11:J11) -> 42410.2 | L11: =IFERROR(K11/K$100,0) -> 0.0012815773
A12: Benefícios | B12: 285 | C12: VALE ALIMENTAÇÃO ASSIDUIDADE | D12: 0 | E12: 0 | F12: 0 | G12: 42 | H12: 490.2 | I12: 0 | J12: 0 | K12: =SUM(D12:J12) -> 532.2 | L12: =IFERROR(K12/K$100,0) -> 1.6082345e-05
A13: Benefícios | B13: 285 | C13: VALE ALIMENTAÇÃO PROPORCIONAL DEMISSIONAL | D13: 0 | E13: 0 | F13: 0 | G13: 90 | H13: 0 | I13: 0 | J13: 0 | K13: =SUM(D13:J13) -> 90 | L13: =IFERROR(K13/K$100,0) -> 2.719675e-06
A14: Benefícios | B14: 285 | C14: VALE ALIMENTAÇÃO/PROPORCIONAL RESC DIF. ASSIDUIDAD | D14: 0 | E14: 739 | F14: 42 | G14: 0 | H14: 0 | I14: 0 | J14: 0 | K14: =SUM(D14:J14) -> 781 | L14: =IFERROR(K14/K$100,0) -> 2.3600735e-05
A15: Descontos | B15: 506 | C15: DESC. AUX ACIDENTARIO INSS | D15: -1780 | E15: -2136 | F15: -142.4 | G15: 0 | H15: 0 | I15: 0 | J15: 0 | K15: =SUM(D15:J15) -> -4058.4 | L15: =IFERROR(K15/K$100,0) -> -0.00012263921
A16: Descontos | B16: 518 | C16: DESCONTO MULTA AUTOMOVEL | D16: 0 | E16: 0 | F16: -162.7 | G16: 0 | H16: 0 | I16: -136.67 | J16: 0 | K16: =SUM(D16:J16) -> -299.37 | L16: =IFERROR(K16/K$100,0) -> -9.0465457e-06
... A98: Taxa e tributos | B98: — | C98: Tributo Fiscal | D98: 734140.84 | E98: 913025.45 | F98: 906753.33 | G98: 700909.91 | H98: 534601.08 | I98: 409080.4 | J98: 528116.43 | K98: =SUM(D98:J98) -> 4726627.4 | L98: =IFERROR(K98/K$100,0) -> 0.14283212
A100: Total geral | D100: =SUM(D5:D98) -> 5181417.3 | E100: =SUM(E5:E98) -> 6501330 | F100: =SUM(F5:F98) -> 6431995.8 | G100: =SUM(G5:G98) -> 4999516.9 | H100: =SUM(H5:H98) -> 3768555.7 | I100: =SUM(I5:I98) -> 3008975.1 | J100: =SUM(J5:J98) -> 3200398.3 | K100: =SUM(K5:K98) -> 33092189

Sheet dRubricas
A1: dRubricas
A2: De-para das verbas de folha. A coluna Grupo é sua — é ela que monta a leitura do Resumo.
A4: Atributo (como vem na origem) | B4: Código | C4: Rubrica | D4: Grupo | E4: Valor no período (R$) | F4: Linhas
A5: 136-REEMB.BENEFICIOS VR | B5: 136 | C5: REEMB.BENEFICIOS VR | D5: Benefícios | E5: 517.61 | F5: 6
A6: 137-REEMB.BENEFICIOS VT | B6: 137 | C6: REEMB.BENEFICIOS VT | D6: Benefícios | E6: 356.04 | F6: 7
A7: 276-PAGAMENTO DE VALE-TRANSPORTE (Valor) | B7: 276 | C7: PAGAMENTO DE VALE-TRANSPORTE (Valor) | D7: Benefícios | E7: 1680909.7 | F7: 4591
A8: 277-VALE REFEIÇÃO (Valor) | B8: 277 | C8: VALE REFEIÇÃO (Valor) | D8: Benefícios | E8: 1084950.4 | F8: 1647
A9: 284-PAGTO DE VALE ALIMENTACAO | B9: 284 | C9: PAGTO DE VALE ALIMENTACAO | D9: Benefícios | E9: 110 | F9: 2
A10: 284-PAGTO DE VALE ALIMENTACAO (Valor) | B10: 284 | C10: PAGTO DE VALE ALIMENTACAO (Valor) | D10: Benefícios | E10: 214283.72 | F10: 1165
A11: 284-PAGTO DE VALE ALIMENTACAO DIF. DISSIDIO (Valor) | B11: 284 | C11: PAGTO DE VALE ALIMENTACAO DIF. DISSIDIO (Valor) | D11: Benefícios | E11: 42410.2 | F11: 230
A12: 285-VALE ALIMENTAÇÃO ASSIDUIDADE | B12: 285 | C12: VALE ALIMENTAÇÃO ASSIDUIDADE | D12: Benefícios | E12: 532.2 | F12: 8
A13: 285-VALE ALIMENTAÇÃO PROPORCIONAL DEMISSIONAL | B13: 285 | C13: VALE ALIMENTAÇÃO PROPORCIONAL DEMISSIONAL | D13: Benefícios | E13: 90 | F13: 1
A14: 285-VALE ALIMENTAÇÃO/PROPORCIONAL RESC DIF. ASSIDUIDAD | B14: 285 | C14: VALE ALIMENTAÇÃO/PROPORCIONAL RESC DIF. ASSIDUIDAD | D14: Benefícios | E14: 781 | F14: 12
A15: 506-DESC. AUX ACIDENTARIO INSS | B15: 506 | C15: DESC. AUX ACIDENTARIO INSS | D15: Descontos | E15: -4058.4 | F15: 3
A16: 518-DESCONTO MULTA AUTOMOVEL | B16: 518 | C16: DESCONTO MULTA AUTOMOVEL | D16: Descontos | E16: -299.37 | F16: 2
... A98: Tributo Fiscal | B98: — | C98: Tributo Fiscal | D98: Taxa e tributos | E98: 4726627.4 | F98: 5638

Sheet dCentroCusto
A1: dCentroCusto
A2: De-para dos centros de custo. 95 grafias na origem viraram 88 centros.
A4: Descrição na origem | B4: Centro de Custo padronizado | C4: Código | D4: Valor no período (R$) | E4: Linhas | F4: Situação
A5: . | B5: . | D5: 4352.23 | E5: 42 | F5: Sem código na origem
A6: 1481 - FILIAL RIO DE JANEIRO | B6: 1481 - FILIAL RIO DE JANEIRO | C6: 1481 | D6: 2554.85 | E6: 11
A7: 1483 - FILIAL FORTALEZA | B7: 1483 - FILIAL FORTALEZA | C7: 1483 | D7: 56904.05 | E7: 201
A8: 1485 - FILIAL SALVADOR | B8: 1485 - FILIAL SALVADOR | C8: 1485 | D8: 156639.98 | E8: 504
A9: 1486 - FILIAL GOIÂNIA | B9: 1486 - FILIAL GOIÂNIA | C9: 1486 | D9: 119978.2 | E9: 342
A10: 1487 - FILIAL CURITIBA | B10: 1487 - FILIAL CURITIBA | C10: 1487 | D10: 448452.27 | E10: 384
A11: 1489 - FILIAL PORTO ALEGRE | B11: 1489 - FILIAL PORTO ALEGRE | C11: 1489 | D11: 58005.11 | E11: 213
A12: 1491 - FILIAL CAMPINAS | B12: 1491 - FILIAL CAMPINAS | C12: 1491 | D12: 12641.47 | E12: 13
A13: 1605 - ADM E MANUTENÇÃO PREDIAL | B13: 1605 - ADM E MANUTENÇÃO PREDIAL | C13: 1605 | D13: 2315.73 | E13: 15
A14: 182 - COMERCIAL MERCADO PÚBLICO | B14: 182 - COMERCIAL MERCADO PÚBLICO | C14: 182 | D14: 59316.45 | E14: 22
A15: 188 - PNLD | B15: 188 - PNLD | C15: 188 | D15: 279254.49 | E15: 248
A16: 188 - VENDAS PNLD | B16: 188 - VENDAS PNLD | C16: 188 | D16: 2874174.9 | E16: 1911
A17: 188- VENDAS PNLD | B17: 188 - VENDAS PNLD | C17: 188 | D17: 932531.09 | E17: 826
... A88: 961 - OPERAÇÕES FINANCEIRAS | B88: 961 - OPERAÇÕES FINANCEIRAS | C88: 961 | D88: 21722.36 | E88: 21
A89: ACABAMENTO NOITE | B89: ACABAMENTO NOITE | D89: 52.77 | E89: 3 | F89: Sem código na origem
A90: EXPEDICAO | B90: EXPEDICAO | D90: 14956.37 | E90: 47 | F90: Sem código na origem
A91: FILIAL - SAO JOSE DOS CAMPOS | B91: FILIAL - SAO JOSE DOS CAMPOS | D91: 105508.53 | E91: 48 | F91: Sem código na origem
A92: FILIAL RECIFE | B92: FILIAL RECIFE | D92: 89895.9 | E92: 279 | F92: Sem código na origem
A93: FTD MACEIO | B93: FTD MACEIO | D93: 39796.13 | E93: 125 | F93: Sem código na origem
A94: PRÉ IMPRESSÃO | B94: PRÉ IMPRESSÃO | D94: 199422.54 | E94: 457 | F94: Sem código na origem
A95: RIBEIRAO PRETO | B95: RIBEIRAO PRETO | D95: 702.94 | E95: 9 | F95: Sem código na origem
A96: ROTATIVA DIA | B96: ROTATIVA DIA | D96: 310.89 | E96: 8 | F96: Sem código na origem
A97: ROTATIVA NOITE | B97: ROTATIVA NOITE | D97: 6184.79 | E97: 14 | F97: Sem código na origem
A98: SOROCABA | B98: SOROCABA | D98: 42746.72 | E98: 38 | F98: Sem código na origem
A100: 11 descrições chegaram sem o código do centro (ex.: "ROTATIVA NOITE" em vez de "650 - ROTATIVA NOITE"), somando R$ 503.929,82 no período. Ficam como centro próprio até alguém confirmar a qual código pertencem — nada foi unificado por conta. Para corrigir, ajuste a célula azul e atualize.
